Workbook

Sheet 입력
B2: 내용 | C2: 입력값 | D2: 비고
B3: 성명 | C3: 홍길동
B4: 주소 | C4: 서울시 중구 중앙로 1길
B5: 주민번호 | C5: 990101-1234567
B6: 연락처 | C6: 010-9999-9999
B7: 근로계약기간 시작일 | C7: 45296
B8: 근로계약기간 종료일 | C8: 45306
B9: 현장명 | C9: ㈜샘플 오피스 인테리어 공사
B10: 직종 | C10: 설비
B11: 일당 | C11: 250000 | D11: =NUMBERSTRING(C11,1)&"원" -> 이십오만원
B12: 지급계좌 | C12: 9999-999-999999 샘플은행
B13: 계약일 | C13: 45296

Sheet 계약서
A1: 현장 일용직 근로계약서
A2: 제 1 조 (당사자 표시)
A3: 사업주 (갑) | C3: 사업체명 | F3: ㈜퍼시스 | P3: 대 표 자 | S3: 박광호
C4: 소 재 지 | F4: 서울특별시 송파구 오금로 311 퍼시스 빌딩 | P4: 연 락 처 | S4: 02-3400-6253
A5: 근로자 (을) | C5: 성 명 | F5: =입력!C3 -> 홍길동 | P5: 주민등록번호 | S5: =입력!C5 -> 990101-1234567
C6: 주 소 | F6: =입력!C4 -> 서울시 중구 중앙로 1길 | P6: 연 락 처 | S6: =입력!C6 -> 010-9999-9999
A8: 제 2 조 (근로계약기간)
A9: ○ 일용직 근로계약기간 : | E9: =입력!C7 -> 45296 | G9: ~ | H9: =입력!C8 -> 45306
A10: 계약기간 내에도 조기에 현장이 종료되거나 "을"의 담당업무 및 공종이 종료된 때 근로계약기간은 자동 만료된다.
A11: ※ 현장 정리, 해당 공종 마무리를 위해 소수의 인원으로 가동하고 있는 경우에도 현장 또는 공종이 종료된 것으로 본다. | AE11: ※포괄일당 산정내역 기준
A12: 아래(①항~②항)와 같은 사유가 발생 시에도 본 근로계약기간은 그 사유발생일에 자동 만료된다. | AE12: 야간 | AF12: =6*0.5*62/72 -> 2.5833333 | AG12: =ROUNDUP(AF12,2) -> 2.59
A13: ① 발주처 또는 원청사의 계약해지, 공사중지 명령, 설계변경, 천재지변 등 기타 불가피한 사유로 인하여 작업이 중단되었을 때 | AE13: 휴일 | AF13: =8*0.5*10/72 -> 0.55555556 | AG13: =ROUNDUP(AF13,2) -> 0.56
A14: ② "을"이 계약기간 내에 타사의 건설현장에 취업 시 또는 "갑"의 동의없이 "을"이 건설현장에 대한 비품, 자산, 현장사진 등을 외부로 유출(사적으로 사용, 처분, 횡령 등 포함)하거나 또는 | AE14: 연장 | AF14: =8*0.5*10/72 -> 0.55555556 | AG14: =ROUNDUP(AF14,2) -> 0.56
A15: 현장 내외부 및 시설물에 대한 사진 촬영을 했을 때 | AE15: 주휴 | AF15: =8*10/72 -> 1.1111111 | AG15: =ROUNDUP(AF15,2) -> 1.12
A17: 제 3 조 (취업장소 및 취업직종)
A18: ① 취업장소: | C18: =입력!C9 -> ㈜샘플 오피스 인테리어 공사 | M18: ② 취업직종: | O18: =입력!C10 -> 설비
A19: ③ 전 ①항 및 ②항은 “갑”의 경영사정에 따라 변경될 수 있으며, 건설업 특성상 “을”이 변경지시(전직 및 배치전환)에 불응 시에는 당해일로부터 근로계약은 자동 해지된다.
Y20: ( 서명 / 인 )
A21: 제 4 조 (근로시간 및 휴게시간 : "갑"의 경영상 필요와 계절의 변화에 의해 변경할 수 있다.)
A22: ① 소정근로시간: | C22: 08:00 - 17:00 (휴일: 08:00 - 17:00) | M22: ② 휴게시간: | O22: 12:00 - 13:00 (휴일: 12:00 ~ 13:00)
A23: ③ 소정근로시간은 1일 8시간, 1주 40시간을 기준으로 하되, 발생할 수 있는 연장근로에 "을"은 동의한다.
A24: ④ "을"이 1주일 중 5일을 소정근로시간동안 근로한 경우 주당 1일을 유급휴일로 부여한다.
A26: 제 5 조 (임금: 포괄일급제)
A27: ① "을"의 임금은 시간급 | E27: =G38/SUM(J37:X37) -> 19485.581 | G27: 1일 8시간 기본일당 | J27: =J38 -> 155884.65 | L27: 으로 하고, 법정수당은 다음과 같이 산정 지급한다.
B28: 1. 연장근로수당 : 시급×연장(주40시간 초과근로)시간×50% | M28: 2. 휴일할증 : 시급×휴일(일)근로시간×50%
B29: 3. 유급주휴수당 : 주 5일 이상 만근한 경우 시급×8시간 | M29: 4. 야간할증 : 시급×야간(밤10시-익일6시)근로시간×50%
B30: ※ 근로기준법 제 56조에 따라 소정 근로시간을 초과하여 근로한 경우, 야간에 근로한 경우 (22:00 ~ 06:00), 휴일에 근로한 경우에는 각각 시간급 통상임금의 50% 가산하여 지급한다.
A32: ② "을"의 임금은 위 "①항" 기본일당에 제반수당이 포함된 포괄일당 | K32: =입력!C11 -> 250000 | M32: 에 동의한다. | O32: ( 서명 / 인 )
A33: ③ 임금은 매월 1일에서 말일까지 정산하여, 익월에 1회 지급한다.
A34: ④ 매월 임금 정산은 세금 및 4대 보험의 공제액 발생 시 “을”의 부담금액을 공제 후 지급한다
A35: ⑤ 지급방법: 근로자 명의 예금통장에 입금 | I35: *지급계좌: | J35: =입력!C12 -> 9999-999-999999 샘플은행
B36: 포괄일당 산정내역 | E36: 임금구성내역 | J36: 기본일당 | M36: 유급주휴 | P36: 연장근로수당 | S36: 야간할증 | V36: 휴일할증
E37: 시간 | J37: 8 | M37: =ROUNDUP(8*10/72,2) -> 1.12 | P37: =ROUNDUP(8*0.5*10/72,2) -> 0.56 | S37: =ROUNDUP(6*0.5*62/72,2) -> 2.59 | V37: =ROUNDUP(8*0.5*10/72,2) -> 0.56
E38: 일당 | G38: =입력!C11 -> 250000 | J38: =E27*J37 -> 155884.65 | M38: =E27*M37 -> 21823.85 | P38: =E27*P37 -> 10911.925 | S38: =E27*S37 -> 50467.654 | V38: =E27*V37 -> 10911.925
A40: 제 6 조 (근로계약 해지사유)
A41: ① 안전수칙(안전용품 미착용 및 안전관리자 지시위반) 불이행 또는 회사규정 불이행으로 경고처분을 받고 현장에 근로를 제공할 수 없을 때
A42: ② 정당한 업무지시 불이행 또는 고의ㆍ중대한 과실로 사고나 손실을 야기시킨 경우
A43: ③ 신체(고혈압, 디스크 포함). 정신상 장애로 현장에서 본 계약에 따른 업무수행이 불가하다고 객관적으로 인정되는 때 인정되었을 때
A44: ④ 외국인근로자 : 법원 및 행정관청의 처분에 따라 사업장에서 외국인과 더 이상 고용관계를 유지할 수 없는 경우(시정지시 또는 처벌일에 근로계약은 해지되는 것에 동의한다)
A45: ⑤ "갑"의 승인없이 타사의 작업현장에 취업한 때 또는 무단결근일을 주 3일 이상 또는 월 5일 이상 했을 때
...
