Workbook

Sheet 표지
A2: 공사 도급 계약서 | N2: Client | R2: =계약서!AH28 -> 주식회사 에이치에스애드
N3: Project | R3: =계약서!AH7 -> HSAD 반포효성빌딩 16층 원상복구 인테리어 공사
N4: Date | R4: =계약서!AH24 -> 2025-08-00
N17: Note | R17: 내용
R40: 퍼플식스 스튜디오 www.purple6.studio | X40: 서울시 송파구 오금로 311, 퍼시스빌딩 meet@purple6.studio

Sheet 계약서
A2: 공사 도급 계약서
AH6: ▼ 여기에 계약서에 채울 내용을 입력해 주세요.
A7: 1. | C7: 공사명 | J7: =IF($AH7=0,"[공사명]",$AH7) -> HSAD 반포효성빌딩 16층 원상복구 인테리어 공사 | AH7: HSAD 반포효성빌딩 16층 원상복구 인테리어 공사
A8: 2. | C8: 공사장소 | J8: =IF($AH8=0,"[공사장소]",$AH8) -> 서울 서초구 반포대로 235 반포효성빌딩 16층 | AH8: 서울 서초구 반포대로 235 반포효성빌딩 16층
A9: 3. | C9: 공사기간 | J9: =IF(OR($AH9=0, $AI9=0, NOT(ISNUMBER($AH9)), NOT(ISNUMBER($AI9))), "[공사기간]", CONCATENATE(TEXT($AH$9,"yyyy년 mm월 dd일")," ~ ",TEXT($AI$9,"yyyy년 mm월 dd일"))) -> 2025년 12월 01일 ~ 2025년 12월 31일 | AH9: 45992 | AI9: 46022
A10: 4. | C10: 총계약금액 | J10: =CONCATENATE("\ ", TEXT(SUM(AH11:AH12), "#,##0"), " (일금 ", NUMBERSTRING(SUM(AH11:AH12), 1), " 원)") -> \ 97,900,000 (일금 구천칠백구십만 원)
C11: 공급가액 | J11: =IF(OR($AH11=0, NOT(ISNUMBER($AH11))), "[공급가액]", CONCATENATE("\ ", TEXT($AH11,"#,##0"), " (일금 ", NUMBERSTRING($AH11,1), " 원)")) -> \ 89,000,000 (일금 팔천구백만 원) | AH11: 89000000
C12: 부가세액 | J12: =IF(OR($AH12=0, NOT(ISNUMBER($AH12))), "[부가세액]", CONCATENATE("\ ", TEXT($AH12,"#,##0"), " (일금 ", NUMBERSTRING($AH12,1), " 원)")) -> \ 8,900,000 (일금 팔백구십만 원) | AH12: =AH11*0.1 -> 8900000
A13: 5. | C13: 계약보증금 | J13: 도급계약금액의 5% (계약이행증권 대체) | AG13: 합 | AH13: =AH11+AH12 -> 97900000
A14: 6. | C14: 하자보수보증금 | J14: 도급계약금액의 10% (하자이행증권 대체)
A15: 7. | C15: 하자담보책임기간 | J15: 준공 완료일로부터 2년
A16: 8. | C16: 지체상금율 | J16: 1日마다 도급금액의 3/1000
A17: 9. | C17: 대금지불 | J17: 지급방법 - 수급사의 지정된 계좌로 현금지급/부가세 포함
J18: 공사비는 "수급사"의 청구에 의하여 다음과 같이 지불하기로 한다.
J19: =CONCATENATE("① 선금 : 계약금액의 30% 일금 ", IF(OR(AH19="", NOT(ISNUMBER(AH19))), "[선금]", NUMBERSTRING(AH19,1)), " 원정 (\ ", IF(OR(AH19="", NOT(ISNUMBER(AH19))), "[선금]", TEXT(AH19,"#,##0")), "/vat포함) - 착공 후 10일 이내") -> ① 선금 : 계약금액의 30% 일금 이천구백삼십칠만 원정 (\ 29,370,000/vat포함) - 착공 후 10일 이내 | AG19: 0.3 | AH19: =AH13*AG19 -> 29370000
J20: =CONCATENATE("② 잔금 : 계약금액의 70% 일금 ", IF(OR(AH20="", NOT(ISNUMBER(AH20))), "[잔금]", NUMBERSTRING(AH20,1)), " 원정 (\ ", IF(OR(AH20="", NOT(ISNUMBER(AH20))), "[잔금]", TEXT(AH20,"#,##0")), "/vat포함)") -> ② 잔금 : 계약금액의 70% 일금 육천팔백오십삼만 원정 (\ 68,530,000/vat포함) | AG20: =1-AG19 -> 0.7 | AH20: =AH13-AH19 -> 68530000
J21: (잔금은 공사완료 및 "도급사"의 검수 완료 후 익월 말까지 지급함)
A23: 상기 인테리어 공사에 관해 당사자는 위 내용과 별첨 인테리어 계약조건에 의하여
A24: 인테리어 계약을 체결하고 계약서 2통을 작성하여 각각 1통씩 보관한다. | T24: =IF($AH24=0,"[날짜]",$AH24) -> 2025-08-00 | AH24: 2025-08-00
A27: 계약주체 | J27: 도급사 | M27: 주소 | T27: =IF($AH27=0,"[주소]",$AH27) -> 서울 마포구 마포대로 155(공덕동,LD마포빌딩) 16층, 17층 | AH27: 서울 마포구 마포대로 155(공덕동,LD마포빌딩) 16층, 17층
M28: 상호 | T28: =IF($AH28=0,"[상호]",$AH28) -> 주식회사 에이치에스애드 | AH28: 주식회사 에이치에스애드
M29: 사업자등록번호 | T29: =IF($AH29=0,"[사업자등록번호]",$AH29) -> 105-81-29368 | AH29: 105-81-29368
M30: 대표자명 | T30: =IF($AH30=0,"[대표자명]",$AH30) -> 박 애 리 | AE30: (인) | AH30: 박 애 리
J32: 수급사 | M32: 주소 | T32: 서울특별시 송파구 오금로 311 퍼시스빌딩
M33: 상호 | T33: ㈜퍼시스
M34: 사업자등록번호 | T34: 215-81-20584
M35: 대표자명 | T35: 박 광 호 | AE35: (인)
R40: 퍼플식스 스튜디오 www.purple6.studio | X40: 서울시 송파구 오금로 311, 퍼시스빌딩 meet@purple6.studio

Sheet 계약조건
A2: 공사 도급 계약조건
A7: 제1조 [총 칙] | I7: =CONCATENATE(IF(계약서!$AH$28=0,"[업체명]",계약서!$AH$28)," (이하 '도급사'라고 한다.)와 ㈜퍼시스 (이하 '수급사'라고 한다.)는") -> 주식회사 에이치에스애드 (이하 '도급사'라고 한다.)와 ㈜퍼시스 (이하 '수급사'라고 한다.)는
I8: 본 공사계약서에 의거 상호 협조하여 각 조항을 신의 성실로써 이행한다.
A10: 제2조 [계약서의 구성] | I10: 본 공사 계약의 내용이 되는 계약 문서는 본 계약서, 공사내역서, 기타 부수되는 서류 일절 및
I11: "도급사", "수급사"가 합의한 일절의 문서 등으로 구성되며 상호 보완적 효력을 가진다.
A13: 제3조 [현장대리인] | I13: ① "수급사"는 착공 전에 현장 대리인을 임명하여 이를 "도급사"에게 통지하여야 한다.
I14: ② 현장 대리인은 공사 현장에 상주하여야 하며, 시공에 관한 일절의 사항에 대하여 "수급사"를 대표한다.
A16: 제4조 [설계변경] | I16: ① "도급사"의 필요에 의하여 설계 변경사항이 발생한 때에는 "도급사"는 사전에 "수급사"에게 통보하며,
I17: 상호 협의 후 "수급사"는 이에 따라 공사를 시행한다.
I18: ② 제 ①항에 의하여 도급금액을 변경할 필요가 있을 때에는 계약시 "도급사", "수급사"가 서로 합의한
I19: 내역서상의 단가에 의하여 그 금액을 정한다.
I20: 단, 내역서상에 명시되지 아니한 사항은 "도급사", "수급사" 쌍방의 합의에 의한다.
A22: 제5조 [공사기간의 연장] | I22: ① "도급사"의 책임있는 사유 또는 천재지변, 불가항력의 사태 등 "수급사"의 책임이 아닌 사유로 공사 수행에
I23: 지체되는 경우에는 당사자간 협의하여 공사기간을 연장할 수 있다.
I24: ② 제 ①항의 규정에 의거 공사 기간이 연장되는 경우 이에 따르는 현장관리비 등 추가 경비를 "수급사"는
I25: "도급사"에게 신청할 수 있다.
I26: ③ | J26: "수급사"의 귀책사유로 공사기간이 연장되고, 그로 인해 "도급인"의 임대차계약 위반이 발생할 경우,
J27: 이에 따른 모든 비용은 전적으로 "수급사"가 부담한다.
A29: 제6조 [부적합한 공사] | I29: ① "도급사"는 "수급사"가 시공한 공사중 설계 도면에 적합하지 아니한 부분이 있을 때에는 이의 시정을
I30: 요구할 수 있다.
I31: ② 제 ①항의 경우 설계 도면에 적합하지 아니한 공사가 "도급사"의 요구 또는 지시에 의하거나
I32: 기타 "수급사"의 책임으로 돌릴 수 없는 사유로 인할 때에는 "수급사"는 그 책임을 지지 아니한다.
A34: 제7조 [지체상금] | I34: ① "수급사"는 공사가 지체되어 계약기간 내에 공사가 완료되지 못한 때에는 1日마다 도급금액의
I35: 3/1000 의 지체상금을 공사 완료일 기준으로 계상하여 공사 잔금에서 공제하여 지급한다.
I36: ② 제 ①항의 경우 정당한 이유가 있을 시 "도급사"는 지체상금을 면제할 수 있다.
A38: 제8조 [하자보증] | I38: 공사의 하자 보증기간은 준공 완료일로부터 2년으로 한다.
I39: (단, A/S발생 시 A/S 처리 기간을 요청 날짜로부터 2개월 이내에 미처리시 하자보증금을 보험사에
I40: 청구하여 하자보수를 진행하기로 함.)
A42: 제9조 [제3자의 권리] | I42: 본 공사의 시공 중 특허권, 기타 제 3자의 권리 대상으로 되어 있는 시공방법을 사용한 때에는
I43: "수급사"는 그 사용에 관한 일절의 책임을 진다. 단, "도급사"의 지시에 의해 시공방법을 결정한 경우는
I44: "도급사"에게 제 3자의 권리 대상으로 되어 있는 시공방법에 관련하여 고지해야하며,
I45: 그럼에도 불구하고 "도급사"가 지시할 경우는 "도급사"가 책임진다.
A47: 제10조 [재해발생 등 사고책임] | I47: ① "수급사"의 책임으로 발생되는 모든 사고는 "수급사"의 책임하에 처리한다.
I48: ② 본 계약으로 인한 모든 공사중 "수급사"의 귀책사유로 발생한 재해 등 책임에 대해서는
I49: "수급사"의 책임으로 하며, 조속히 해결하여 "도급사" 에게 하등의 민,형사상의 피해가 없도록 한다.
A51: 제11조 [권리양도] | I51: "수급사"는 본 계약에 관한 채권을 제3자에게 양도할 수 없다.
A54: 제12조 [공사 특기 사항] | I54: ① 본 공사에 사용하는 모든 자재는 KS품을 사용하여야 하고 "수급사"는 자재 사용전에 "도급사"의 검사를
I55: 받아 합격된 자재만을 사용하여야한다.
I56: ② "도급사"는 "수급사"가 설계업무를 수행하는데 필요한 다음 각호의 자료 또는 제반사항을 요구할 때에는
I57: 즉시 제공하여야 한다.
...
